
Epoch 1/50:   0%|          | 0/2049 [01:45<?, ?img/s]
Traceback (most recent call last):
  File "C:\Users\Mircea\Desktop\Computer Vision and Deep Learning\L4_Semantic_Segmentation_1\train.py", line 136, in <module>
    train_model()
  File "C:\Users\Mircea\Desktop\Computer Vision and Deep Learning\L4_Semantic_Segmentation_1\train.py", line 65, in train_model
    for batch in train_loader:
  File "C:\Users\Mircea\AppData\Local\Programs\Python\Python39\lib\site-packages\torch\utils\data\dataloader.py", line 630, in __next__
    data = self._next_data()
  File "C:\Users\Mircea\AppData\Local\Programs\Python\Python39\lib\site-packages\torch\utils\data\dataloader.py", line 1345, in _next_data
    return self._process_data(data)
  File "C:\Users\Mircea\AppData\Local\Programs\Python\Python39\lib\site-packages\torch\utils\data\dataloader.py", line 1371, in _process_data
    data.reraise()
  File "C:\Users\Mircea\AppData\Local\Programs\Python\Python39\lib\site-packages\torch\_utils.py", line 694, in reraise
    raise exception
RuntimeError: Caught RuntimeError in DataLoader worker process 0.
Original Traceback (most recent call last):
  File "C:\Users\Mircea\AppData\Local\Programs\Python\Python39\lib\site-packages\torch\utils\data\_utils\worker.py", line 308, in _worker_loop
    data = fetcher.fetch(index)
  File "C:\Users\Mircea\AppData\Local\Programs\Python\Python39\lib\site-packages\torch\utils\data\_utils\fetch.py", line 54, in fetch
    return self.collate_fn(data)
  File "C:\Users\Mircea\AppData\Local\Programs\Python\Python39\lib\site-packages\torch\utils\data\_utils\collate.py", line 265, in default_collate
    return collate(batch, collate_fn_map=default_collate_fn_map)
  File "C:\Users\Mircea\AppData\Local\Programs\Python\Python39\lib\site-packages\torch\utils\data\_utils\collate.py", line 127, in collate
    return elem_type({key: collate([d[key] for d in batch], collate_fn_map=collate_fn_map) for key in elem})
  File "C:\Users\Mircea\AppData\Local\Programs\Python\Python39\lib\site-packages\torch\utils\data\_utils\collate.py", line 127, in <dictcomp>
    return elem_type({key: collate([d[key] for d in batch], collate_fn_map=collate_fn_map) for key in elem})
  File "C:\Users\Mircea\AppData\Local\Programs\Python\Python39\lib\site-packages\torch\utils\data\_utils\collate.py", line 119, in collate
    return collate_fn_map[elem_type](batch, collate_fn_map=collate_fn_map)
  File "C:\Users\Mircea\AppData\Local\Programs\Python\Python39\lib\site-packages\torch\utils\data\_utils\collate.py", line 171, in collate_numpy_array_fn
    return collate([torch.as_tensor(b) for b in batch], collate_fn_map=collate_fn_map)
  File "C:\Users\Mircea\AppData\Local\Programs\Python\Python39\lib\site-packages\torch\utils\data\_utils\collate.py", line 119, in collate
    return collate_fn_map[elem_type](batch, collate_fn_map=collate_fn_map)
  File "C:\Users\Mircea\AppData\Local\Programs\Python\Python39\lib\site-packages\torch\utils\data\_utils\collate.py", line 160, in collate_tensor_fn
    storage = elem._typed_storage()._new_shared(numel, device=elem.device)
  File "C:\Users\Mircea\AppData\Local\Programs\Python\Python39\lib\site-packages\torch\storage.py", line 866, in _new_shared
    untyped_storage = torch.UntypedStorage._new_shared(size * self._element_size(), device=device)
  File "C:\Users\Mircea\AppData\Local\Programs\Python\Python39\lib\site-packages\torch\storage.py", line 260, in _new_shared
    return cls._new_using_filename_cpu(size)
RuntimeError: Couldn't open shared file mapping: <000001DC3E65CD32>, error code: <1455>